Creating test database for alias 'default'...
.E
======================================================================
ERROR: test_view_teacher_student (main.tests.ViewsTestCase)
----------------------------------------------------------------------
Traceback (most recent call last):
  File "/Users/mariazyryanova/Desktop/BSUIR/2 course/4 sem/ИСП/ISP-2022-053503/web/main/tests.py", line 134, in setUp
    mark.save()
  File "/Users/mariazyryanova/Desktop/BSUIR/2 course/4 sem/ИСП/ISP-2022-053503/myenv/lib/python3.9/site-packages/django/db/models/base.py", line 806, in save
    self.save_base(
  File "/Users/mariazyryanova/Desktop/BSUIR/2 course/4 sem/ИСП/ISP-2022-053503/myenv/lib/python3.9/site-packages/django/db/models/base.py", line 857, in save_base
    updated = self._save_table(
  File "/Users/mariazyryanova/Desktop/BSUIR/2 course/4 sem/ИСП/ISP-2022-053503/myenv/lib/python3.9/site-packages/django/db/models/base.py", line 1000, in _save_table
    results = self._do_insert(
  File "/Users/mariazyryanova/Desktop/BSUIR/2 course/4 sem/ИСП/ISP-2022-053503/myenv/lib/python3.9/site-packages/django/db/models/base.py", line 1041, in _do_insert
    return manager._insert(
  File "/Users/mariazyryanova/Desktop/BSUIR/2 course/4 sem/ИСП/ISP-2022-053503/myenv/lib/python3.9/site-packages/django/db/models/manager.py", line 85, in manager_method
    return getattr(self.get_queryset(), name)(*args, **kwargs)
  File "/Users/mariazyryanova/Desktop/BSUIR/2 course/4 sem/ИСП/ISP-2022-053503/myenv/lib/python3.9/site-packages/django/db/models/query.py", line 1434, in _insert
    return query.get_compiler(using=using).execute_sql(returning_fields)
  File "/Users/mariazyryanova/Desktop/BSUIR/2 course/4 sem/ИСП/ISP-2022-053503/myenv/lib/python3.9/site-packages/django/db/models/sql/compiler.py", line 1620, in execute_sql
    for sql, params in self.as_sql():
  File "/Users/mariazyryanova/Desktop/BSUIR/2 course/4 sem/ИСП/ISP-2022-053503/myenv/lib/python3.9/site-packages/django/db/models/sql/compiler.py", line 1547, in as_sql
    value_rows = [
  File "/Users/mariazyryanova/Desktop/BSUIR/2 course/4 sem/ИСП/ISP-2022-053503/myenv/lib/python3.9/site-packages/django/db/models/sql/compiler.py", line 1548, in <listcomp>
    [
  File "/Users/mariazyryanova/Desktop/BSUIR/2 course/4 sem/ИСП/ISP-2022-053503/myenv/lib/python3.9/site-packages/django/db/models/sql/compiler.py", line 1549, in <listcomp>
    self.prepare_value(field, self.pre_save_val(field, obj))
  File "/Users/mariazyryanova/Desktop/BSUIR/2 course/4 sem/ИСП/ISP-2022-053503/myenv/lib/python3.9/site-packages/django/db/models/sql/compiler.py", line 1487, in prepare_value
    value = field.get_db_prep_save(value, connection=self.connection)
  File "/Users/mariazyryanova/Desktop/BSUIR/2 course/4 sem/ИСП/ISP-2022-053503/myenv/lib/python3.9/site-packages/django/db/models/fields/__init__.py", line 910, in get_db_prep_save
    return self.get_db_prep_value(value, connection=connection, prepared=False)
  File "/Users/mariazyryanova/Desktop/BSUIR/2 course/4 sem/ИСП/ISP-2022-053503/myenv/lib/python3.9/site-packages/django/db/models/fields/__init__.py", line 1408, in get_db_prep_value
    value = self.get_prep_value(value)
  File "/Users/mariazyryanova/Desktop/BSUIR/2 course/4 sem/ИСП/ISP-2022-053503/myenv/lib/python3.9/site-packages/django/db/models/fields/__init__.py", line 1403, in get_prep_value
    return self.to_python(value)
  File "/Users/mariazyryanova/Desktop/BSUIR/2 course/4 sem/ИСП/ISP-2022-053503/myenv/lib/python3.9/site-packages/django/db/models/fields/__init__.py", line 1369, in to_python
    raise exceptions.ValidationError(
django.core.exceptions.ValidationError: ['Значение “07.09.2021” имеет неверный формат даты. Оно должно быть в формате YYYY-MM-DD.']

----------------------------------------------------------------------
Ran 2 tests in 0.006s

FAILED (errors=1)
Destroying test database for alias 'default'...
